<robot name="human_hand">

<link name="body">
	<visual>
    <origin xyz="0 0 0" rpy="0 0 0" />
    <geometry>
      <cylinder radius="0.1" length=".5" />
    </geometry>
    <material name="gray">
      <color rgba=".2 .2 .2 1" />
    </material>
	</visual>
</link>

<link name="upper_arm">
  <visual>
    <origin xyz="0 0 0.25" rpy="0 0 0" />
    <geometry>
      <cylinder radius="0.01" length=".5" />
    </geometry>
    <material name="gray">
      <color rgba=".2 .2 .2 1" />
    </material>
	</visual>
</link>

<link name="upper_arm_x">
  <visual>
    <origin xyz="0 0 0" rpy="0 0 0" />
    <geometry>
      <cylinder radius="0.00" length="0.0" />
    </geometry>
	</visual>
</link> 

<link name="palm">
  <visual>
    <origin xyz="0 0 0" rpy="0 1.57 0" />
    <geometry>
      <cylinder radius="0.005" length="0.1" />
    </geometry>
	</visual>
</link>

<link name="upper_arm_y">
  <visual>
    <origin xyz="0 0 0" rpy="0 0 0" />
    <geometry>
      <cylinder radius="0.00" length="0.0" />
    </geometry>
	</visual>
</link> 

<joint name="shoulder_joint_x" type="continuous">
   <axis xyz="1 0 0" />
	 <origin xyz="0 0.1 0.1" />
   <parent link="body"/>
	 <child link="upper_arm_x"/>
</joint>

<joint name="shoulder_joint_y" type="continuous">
   <axis xyz="0 1 0" />
	 <origin xyz="0 0 0" />
   <parent link="upper_arm_x"/>
	 <child link="upper_arm_y"/>
</joint> 

<joint name="shoulder_joint_z" type="continuous">
   <axis xyz="0 0 1" />
	 <origin xyz="0 0 0" />
   <parent link="upper_arm_y"/>
	 <child link="upper_arm"/>
</joint> 

<joint name="shoulder_palm" type="fixed">
   <origin xyz="0 0 0.5" />
	 <parent link="upper_arm"/>
	 <child link="palm"/>
</joint> 
</robot>
